<?xml version="1.0"?>

<robot name="two_wheel_robot">


<link name="body_link">
  <inertial>
    <mass value="0.3" />
    <origin xyz="0 0 0.0127" />
    <inertia ixx="0.000032258" ixy="0.0" ixz="0.0"
      iyy="0.000032258" iyz="0.0"
      izz="0.000032258" />
  </inertial>

  <visual>
    <origin xyz="0 0 0.0127" />
    <geometry>
      <box size="0.0254 0.0254 0.0254"/>
    </geometry>
  </visual>

  <collision>
    <origin xyz="0 0 0.0127" />
    <geometry>
      <box size="0.0254 0.0254 0.0254"/>
    </geometry>
  </collision>
</link>

<gazebo reference="body_link">
  <!-- tag name has to be mu1, though in gazebo they are mu and mu2 -->
  <mu1>0.1</mu1>
  <mu2>0.1</mu2>
  <material>Gazebo/Grey</material>
</gazebo>


<link name="left_wheel">
  <inertial>
    <mass value="0.01" />
    <origin xyz="0 0 0.002" />
    <inertia ixx="0.00000005659" ixy="0.0" ixz="0.0"
      iyy="0.00000005659" iyz="0.0"
      izz="0.0000001125" />
  </inertial>

  <visual>
    <origin xyz="0 0 0.002" />
    <geometry>
      <cylinder radius="0.015" length="0.004" />
    </geometry>
  </visual>

  <collision>
    <origin xyz="0 0 0.002" />
    <geometry>
      <cylinder radius="0.015" length="0.004" />
    </geometry>
  </collision>
</link>

<gazebo reference="left_wheel">
  <mu1>100</mu1>
  <mu2>50</mu2>
  <material>Gazebo/Red</material>
</gazebo>


<link name="right_wheel">
  <inertial>
    <mass value="0.01" />
    <origin xyz="0 0 0.002" />
    <inertia ixx="0.00000005659" ixy="0.0" ixz="0.0"
      iyy="0.00000005659" iyz="0.0"
      izz="0.0000001125" />
  </inertial>

  <visual>
    <origin xyz="0 0 0.002" />
    <geometry>
      <cylinder radius="0.015" length="0.004" />
    </geometry>
  </visual>

  <collision>
    <origin xyz="0 0 0.002" />
    <geometry>
      <cylinder radius="0.015" length="0.004" />
    </geometry>
  </collision>
</link>

<gazebo reference="right_wheel">
  <mu1>100</mu1>
  <mu2>50</mu2>
  <material>Gazebo/Blue</material>
</gazebo>


<joint name="left_motor" type="continuous">
  <parent link="body_link" />
  <child link="left_wheel" />
  <!-- <origin xyz="0 -0.0177 0.0127" rpy="-1.5708 0 0" /> -->
  <origin xyz="0 0.0177 0.0127" rpy="1.5708 0 0" />
<!--   this is very weird, the uncommented one is more reasonable
  but the uncommented one demonstrate the right position and rotation in gazebo -->
  <axis xyz="0 0 -1" />
<!--   important axis setting here, with the corresponding setting in right_motor
  two wheels are tuned at the same direction, which means
  when the same wheel position command is given, both wheels will make the same effect
  of pushing the robot forward or backward -->
</joint>


<joint name="right_motor" type="continuous">
  <parent link="body_link" />
  <child link="right_wheel" />
  <!-- <origin xyz="0 0.0177 0.0127" rpy="1.5708 0 0" /> -->
  <origin xyz="0 -0.0177 0.0127" rpy="-1.5708 0 0" />
  <axis xyz="0 0 1" />

</joint>

<link name="lidar_link">
      <collision>
          <origin xyz="0 0 0" rpy="0 0 0"/>
          <geometry>              
             <box size="0.0254 0.0254 0.00154"/>
          </geometry>
      </collision>

      <visual>
          <origin xyz="0 0 0" rpy="0 0 0" />
          <geometry>
                    <box size="0.0254 0.0254 0.00054"/>
          </geometry>
      </visual>

      <inertial>
          <mass value="0.0005" />
          <origin xyz="0 0 0" rpy="0 0 0"/>
          <inertia ixx="0.000032258" ixy="0" ixz="0" iyy="0.000032258" iyz="0" izz="0.000032258" />
      </inertial>
  </link>
  

  <joint name="lidar_joint" type="fixed">
      <axis xyz="0 1 0" />
      <origin xyz="0 0 0" rpy="0 0 0"/>
      <parent link="body_link"/>
      <child link="lidar_link"/>
  </joint>
  
  <gazebo reference="lidar_link">
    <mu1>100.0</mu1>
    <mu2>50.0</mu2>
    <material>Gazebo/Purple</material>

    <sensor type="gpu_ray" name="sick_lidar_sensor">
      <pose>0 0 0 0 0 0</pose>
      <visualize>false</visualize>
      <update_rate>40</update_rate>
      <ray>
        <scan>
          <horizontal>
            <samples>181</samples>
            <resolution>1</resolution>
            <min_angle>-3.140796</min_angle>
            <max_angle>3.140796</max_angle>
          </horizontal>
        </scan>
        <range>
          <min>0.10</min>
          <max>40.0</max>
          <resolution>0.01</resolution>
        </range>
        <noise>
          <type>gaussian</type>
          <mean>0.0</mean>
          <stddev>0.01</stddev>
        </noise>
      </ray>
      <plugin name="gazebo_ros_lidar_controller" filename="libgazebo_ros_gpu_laser.so">
        <topicName>/scan1</topicName>
        <frameName>lidar_link</frameName>
      </plugin>
    </sensor>
  </gazebo>  

</robot>
